[2025-02-13T19:43:19.051+0000] {taskinstance.py:1159} INFO - Dependencies all met for dep_context=non-requeueable deps ti=<TaskInstance: download_dataset.commit_push_dvc manual__2025-02-13T19:42:47.384317+00:00 [queued]>
[2025-02-13T19:43:19.063+0000] {taskinstance.py:1159} INFO - Dependencies all met for dep_context=requeueable deps ti=<TaskInstance: download_dataset.commit_push_dvc manual__2025-02-13T19:42:47.384317+00:00 [queued]>
[2025-02-13T19:43:19.063+0000] {taskinstance.py:1361} INFO - Starting attempt 1 of 2
[2025-02-13T19:43:19.078+0000] {taskinstance.py:1382} INFO - Executing <Task(BashOperator): commit_push_dvc> on 2025-02-13 19:42:47.384317+00:00
[2025-02-13T19:43:19.084+0000] {standard_task_runner.py:57} INFO - Started process 1921 to run task
[2025-02-13T19:43:19.087+0000] {standard_task_runner.py:84} INFO - Running: ['***', 'tasks', 'run', 'download_dataset', 'commit_push_dvc', 'manual__2025-02-13T19:42:47.384317+00:00', '--job-id', '68', '--raw', '--subdir', 'DAGS_FOLDER/download_dataset_dag.py', '--cfg-path', '/tmp/tmpp5znygl3']
[2025-02-13T19:43:19.088+0000] {standard_task_runner.py:85} INFO - Job 68: Subtask commit_push_dvc
[2025-02-13T19:43:19.138+0000] {task_command.py:416} INFO - Running <TaskInstance: download_dataset.commit_push_dvc manual__2025-02-13T19:42:47.384317+00:00 [running]> on host f09fff4ef036
[2025-02-13T19:43:19.224+0000] {taskinstance.py:1662} INFO - Exporting env vars: AIRFLOW_CTX_DAG_OWNER='***' AIRFLOW_CTX_DAG_ID='download_dataset' AIRFLOW_CTX_TASK_ID='commit_push_dvc' AIRFLOW_CTX_EXECUTION_DATE='2025-02-13T19:42:47.384317+00:00' AIRFLOW_CTX_TRY_NUMBER='1' AIRFLOW_CTX_DAG_RUN_ID='manual__2025-02-13T19:42:47.384317+00:00'
[2025-02-13T19:43:19.226+0000] {subprocess.py:63} INFO - Tmp dir root location: /tmp
[2025-02-13T19:43:19.226+0000] {subprocess.py:75} INFO - Running command: ['/bin/bash', '-c', '\n    cd /opt/***/{DATA_REPO_NAME}\n\n    # Ensure DVC is initialized\n    if [ ! -d .dvc ]; then\n        dvc init\n    fi\n\n    # Ensure DVC remote is set only if it doesn\'t exist\n    if ! dvc remote list | grep -q "origin"; then\n        dvc remote add origin "{S3_URL}"\n    fi\n\n    # Configure Git User\n    git config --global user.email "bencappello@gmail.com"\n    git config --global user.name "Ben Cappello"\n\n    # Add files to DVC tracking\n    dvc add Telco-Customer-Churn-Transformed.csv\n    dvc add Telco-Customer-Churn-Transformed.parquet\n\n    # Ensure Git tracks DVC metadata files\n    git add .gitignore\n    if [ -f Telco-Customer-Churn-Transformed.csv.dvc ]; then git add Telco-Customer-Churn-Transformed.csv.dvc; fi\n    if [ -f Telco-Customer-Churn-Transformed.parquet.dvc ]; then git add Telco-Customer-Churn-Transformed.parquet.dvc; fi\n    if [ -f dvc.yaml ]; then git add dvc.yaml; fi\n    if [ -f dvc.lock ]; then git add dvc.lock; fi\n\n    # Commit changes to Git\n    git commit -m "Add transformed dataset and Parquet file" || echo "No changes to commit"\n\n    # Ensure correct Git branch and push\n    git branch -M main\n    git push origin main\n\n    # Push dataset files to DVC remote storage (S3)\n    dvc push\n    ']
[2025-02-13T19:43:19.241+0000] {subprocess.py:86} INFO - Output:
[2025-02-13T19:43:19.243+0000] {subprocess.py:93} INFO - /bin/bash: line 2: cd: /opt/***/{DATA_REPO_NAME}: No such file or directory
[2025-02-13T19:43:20.096+0000] {subprocess.py:93} INFO - ERROR: failed to initiate DVC - /tmp/***tmp_sorra5x is not tracked by any supported SCM tool (e.g. Git). Use `--no-scm` if you don't want to use any SCM or `--subdir` if initializing inside a subdirectory of a parent SCM repository.
[2025-02-13T19:43:21.925+0000] {subprocess.py:93} INFO - ERROR: configuration error - config file error: Not inside a DVC repo
[2025-02-13T19:43:23.027+0000] {subprocess.py:93} INFO - ERROR: you are not inside of a DVC repository (checked up to mount point '/')
[2025-02-13T19:43:24.033+0000] {subprocess.py:93} INFO - ERROR: you are not inside of a DVC repository (checked up to mount point '/')
[2025-02-13T19:43:24.171+0000] {subprocess.py:93} INFO - fatal: not a git repository (or any of the parent directories): .git
[2025-02-13T19:43:24.173+0000] {subprocess.py:93} INFO - fatal: not a git repository (or any of the parent directories): .git
[2025-02-13T19:43:24.174+0000] {subprocess.py:93} INFO - No changes to commit
[2025-02-13T19:43:24.176+0000] {subprocess.py:93} INFO - fatal: not a git repository (or any of the parent directories): .git
[2025-02-13T19:43:24.178+0000] {subprocess.py:93} INFO - fatal: not a git repository (or any of the parent directories): .git
[2025-02-13T19:43:25.061+0000] {subprocess.py:93} INFO - ERROR: you are not inside of a DVC repository (checked up to mount point '/')
[2025-02-13T19:43:25.200+0000] {subprocess.py:97} INFO - Command exited with return code 253
[2025-02-13T19:43:25.212+0000] {taskinstance.py:1937} ERROR - Task failed with exception
Traceback (most recent call last):
  File "/home/airflow/.local/lib/python3.8/site-packages/airflow/operators/bash.py", line 210, in execute
    raise AirflowException(
airflow.exceptions.AirflowException: Bash command failed. The command returned a non-zero exit code 253.
[2025-02-13T19:43:25.215+0000] {taskinstance.py:1400} INFO - Marking task as UP_FOR_RETRY. dag_id=download_dataset, task_id=commit_push_dvc, execution_date=20250213T194247, start_date=20250213T194319, end_date=20250213T194325
[2025-02-13T19:43:25.231+0000] {standard_task_runner.py:104} ERROR - Failed to execute job 68 for task commit_push_dvc (Bash command failed. The command returned a non-zero exit code 253.; 1921)
[2025-02-13T19:43:25.245+0000] {local_task_job_runner.py:228} INFO - Task exited with return code 1
[2025-02-13T19:43:25.262+0000] {taskinstance.py:2778} INFO - 0 downstream tasks scheduled from follow-on schedule check
