[2025-02-13T05:19:13.305+0000] {taskinstance.py:1159} INFO - Dependencies all met for dep_context=non-requeueable deps ti=<TaskInstance: download_dataset.download_dataset manual__2025-02-13T05:19:11.716827+00:00 [queued]>
[2025-02-13T05:19:13.313+0000] {taskinstance.py:1159} INFO - Dependencies all met for dep_context=requeueable deps ti=<TaskInstance: download_dataset.download_dataset manual__2025-02-13T05:19:11.716827+00:00 [queued]>
[2025-02-13T05:19:13.314+0000] {taskinstance.py:1361} INFO - Starting attempt 1 of 2
[2025-02-13T05:19:13.327+0000] {taskinstance.py:1382} INFO - Executing <Task(BashOperator): download_dataset> on 2025-02-13 05:19:11.716827+00:00
[2025-02-13T05:19:13.332+0000] {standard_task_runner.py:57} INFO - Started process 809 to run task
[2025-02-13T05:19:13.335+0000] {standard_task_runner.py:84} INFO - Running: ['***', 'tasks', 'run', 'download_dataset', 'download_dataset', 'manual__2025-02-13T05:19:11.716827+00:00', '--job-id', '7', '--raw', '--subdir', 'DAGS_FOLDER/download_dataset_dag.py', '--cfg-path', '/tmp/tmp_lb9odku']
[2025-02-13T05:19:13.336+0000] {standard_task_runner.py:85} INFO - Job 7: Subtask download_dataset
[2025-02-13T05:19:13.386+0000] {task_command.py:416} INFO - Running <TaskInstance: download_dataset.download_dataset manual__2025-02-13T05:19:11.716827+00:00 [running]> on host 149dba22e345
[2025-02-13T05:19:13.465+0000] {taskinstance.py:1662} INFO - Exporting env vars: AIRFLOW_CTX_DAG_OWNER='***' AIRFLOW_CTX_DAG_ID='download_dataset' AIRFLOW_CTX_TASK_ID='download_dataset' AIRFLOW_CTX_EXECUTION_DATE='2025-02-13T05:19:11.716827+00:00' AIRFLOW_CTX_TRY_NUMBER='1' AIRFLOW_CTX_DAG_RUN_ID='manual__2025-02-13T05:19:11.716827+00:00'
[2025-02-13T05:19:13.466+0000] {subprocess.py:63} INFO - Tmp dir root location: /tmp
[2025-02-13T05:19:13.466+0000] {subprocess.py:75} INFO - Running command: ['/bin/bash', '-c', 'kaggle datasets download -d blastchar/telco-customer-churn -p /opt/***/<<GIT REPOSITORY NAME>> --unzip']
[2025-02-13T05:19:13.479+0000] {subprocess.py:86} INFO - Output:
[2025-02-13T05:19:13.481+0000] {subprocess.py:93} INFO - /bin/bash: line 1: warning: here-document at line 1 delimited by end-of-file (wanted `GIT')
[2025-02-13T05:19:14.130+0000] {subprocess.py:93} INFO - usage: kaggle [-h] [-v] [-W]
[2025-02-13T05:19:14.130+0000] {subprocess.py:93} INFO -               {competitions,c,datasets,d,kernels,k,models,m,files,f,config}
[2025-02-13T05:19:14.130+0000] {subprocess.py:93} INFO -               ...
[2025-02-13T05:19:14.130+0000] {subprocess.py:93} INFO - kaggle: error: unrecognized arguments: NAME
[2025-02-13T05:19:14.159+0000] {subprocess.py:97} INFO - Command exited with return code 2
[2025-02-13T05:19:14.174+0000] {taskinstance.py:1937} ERROR - Task failed with exception
Traceback (most recent call last):
  File "/home/airflow/.local/lib/python3.8/site-packages/airflow/operators/bash.py", line 210, in execute
    raise AirflowException(
airflow.exceptions.AirflowException: Bash command failed. The command returned a non-zero exit code 2.
[2025-02-13T05:19:14.178+0000] {taskinstance.py:1400} INFO - Marking task as UP_FOR_RETRY. dag_id=download_dataset, task_id=download_dataset, execution_date=20250213T051911, start_date=20250213T051913, end_date=20250213T051914
[2025-02-13T05:19:14.194+0000] {standard_task_runner.py:104} ERROR - Failed to execute job 7 for task download_dataset (Bash command failed. The command returned a non-zero exit code 2.; 809)
[2025-02-13T05:19:14.234+0000] {local_task_job_runner.py:228} INFO - Task exited with return code 1
[2025-02-13T05:19:14.257+0000] {taskinstance.py:2778} INFO - 0 downstream tasks scheduled from follow-on schedule check
