[2025-02-13T05:47:29.054+0000] {taskinstance.py:1159} INFO - Dependencies all met for dep_context=non-requeueable deps ti=<TaskInstance: download_dataset.verify_dataset manual__2025-02-13T05:47:26.138325+00:00 [queued]>
[2025-02-13T05:47:29.062+0000] {taskinstance.py:1159} INFO - Dependencies all met for dep_context=requeueable deps ti=<TaskInstance: download_dataset.verify_dataset manual__2025-02-13T05:47:26.138325+00:00 [queued]>
[2025-02-13T05:47:29.062+0000] {taskinstance.py:1361} INFO - Starting attempt 1 of 2
[2025-02-13T05:47:29.075+0000] {taskinstance.py:1382} INFO - Executing <Task(BashOperator): verify_dataset> on 2025-02-13 05:47:26.138325+00:00
[2025-02-13T05:47:29.081+0000] {standard_task_runner.py:57} INFO - Started process 140 to run task
[2025-02-13T05:47:29.084+0000] {standard_task_runner.py:84} INFO - Running: ['***', 'tasks', 'run', 'download_dataset', 'verify_dataset', 'manual__2025-02-13T05:47:26.138325+00:00', '--job-id', '14', '--raw', '--subdir', 'DAGS_FOLDER/download_dataset_dag.py', '--cfg-path', '/tmp/tmpi2vz0r59']
[2025-02-13T05:47:29.086+0000] {standard_task_runner.py:85} INFO - Job 14: Subtask verify_dataset
[2025-02-13T05:47:29.133+0000] {task_command.py:416} INFO - Running <TaskInstance: download_dataset.verify_dataset manual__2025-02-13T05:47:26.138325+00:00 [running]> on host 081769f0e6bd
[2025-02-13T05:47:29.211+0000] {taskinstance.py:1662} INFO - Exporting env vars: AIRFLOW_CTX_DAG_OWNER='***' AIRFLOW_CTX_DAG_ID='download_dataset' AIRFLOW_CTX_TASK_ID='verify_dataset' AIRFLOW_CTX_EXECUTION_DATE='2025-02-13T05:47:26.138325+00:00' AIRFLOW_CTX_TRY_NUMBER='1' AIRFLOW_CTX_DAG_RUN_ID='manual__2025-02-13T05:47:26.138325+00:00'
[2025-02-13T05:47:29.212+0000] {subprocess.py:63} INFO - Tmp dir root location: /tmp
[2025-02-13T05:47:29.212+0000] {subprocess.py:75} INFO - Running command: ['/bin/bash', '-c', 'ls -lh /opt/***/basic-pipeline/Telco-Customer-Churn.csv']
[2025-02-13T05:47:29.225+0000] {subprocess.py:86} INFO - Output:
[2025-02-13T05:47:29.229+0000] {subprocess.py:93} INFO - ls: cannot access '/opt/***/basic-pipeline/Telco-Customer-Churn.csv': No such file or directory
[2025-02-13T05:47:29.230+0000] {subprocess.py:97} INFO - Command exited with return code 2
[2025-02-13T05:47:29.245+0000] {taskinstance.py:1937} ERROR - Task failed with exception
Traceback (most recent call last):
  File "/home/airflow/.local/lib/python3.8/site-packages/airflow/operators/bash.py", line 210, in execute
    raise AirflowException(
airflow.exceptions.AirflowException: Bash command failed. The command returned a non-zero exit code 2.
[2025-02-13T05:47:29.249+0000] {taskinstance.py:1400} INFO - Marking task as UP_FOR_RETRY. dag_id=download_dataset, task_id=verify_dataset, execution_date=20250213T054726, start_date=20250213T054729, end_date=20250213T054729
[2025-02-13T05:47:29.262+0000] {standard_task_runner.py:104} ERROR - Failed to execute job 14 for task verify_dataset (Bash command failed. The command returned a non-zero exit code 2.; 140)
[2025-02-13T05:47:29.297+0000] {local_task_job_runner.py:228} INFO - Task exited with return code 1
[2025-02-13T05:47:29.314+0000] {taskinstance.py:2778} INFO - 0 downstream tasks scheduled from follow-on schedule check
